Traceback (most recent call last):
  File "/opt/hostedtoolcache/Python/3.10.4/x64/lib/python3.10/site-packages/jupyter_cache/executors/utils.py", line 51, in single_nb_execution
    executenb(
  File "/opt/hostedtoolcache/Python/3.10.4/x64/lib/python3.10/site-packages/nbclient/client.py", line 1204, in execute
    return NotebookClient(nb=nb, resources=resources, km=km, **kwargs).execute()
  File "/opt/hostedtoolcache/Python/3.10.4/x64/lib/python3.10/site-packages/nbclient/util.py", line 84, in wrapped
    return just_run(coro(*args, **kwargs))
  File "/opt/hostedtoolcache/Python/3.10.4/x64/lib/python3.10/site-packages/nbclient/util.py", line 62, in just_run
    return loop.run_until_complete(coro)
  File "/opt/hostedtoolcache/Python/3.10.4/x64/lib/python3.10/asyncio/base_events.py", line 646, in run_until_complete
    return future.result()
  File "/opt/hostedtoolcache/Python/3.10.4/x64/lib/python3.10/site-packages/nbclient/client.py", line 663, in async_execute
    await self.async_execute_cell(
  File "/opt/hostedtoolcache/Python/3.10.4/x64/lib/python3.10/site-packages/nbclient/client.py", line 965, in async_execute_cell
    await self._check_raise_for_error(cell, cell_index, exec_reply)
  File "/opt/hostedtoolcache/Python/3.10.4/x64/lib/python3.10/site-packages/nbclient/client.py", line 862, in _check_raise_for_error
    raise CellExecutionError.from_cell_and_msg(cell, exec_reply_content)
nbclient.exceptions.CellExecutionError: An error occurred while executing the following cell:
------------------
from utils import carrega_dataset

dataset = carrega_dataset()
dataset

------------------

[0;31m---------------------------------------------------------------------------[0m
[0;31mModuleNotFoundError[0m                       Traceback (most recent call last)
Input [0;32mIn [1][0m, in [0;36m<cell line: 1>[0;34m()[0m
[0;32m----> 1[0m [38;5;28;01mfrom[39;00m [38;5;21;01mutils[39;00m [38;5;28;01mimport[39;00m carrega_dataset
[1;32m      3[0m dataset [38;5;241m=[39m carrega_dataset()
[1;32m      4[0m dataset

File [0;32m~/work/Seminario_Nao_Parametrica/Seminario_Nao_Parametrica/src/utils/__init__.py:1[0m, in [0;36m<module>[0;34m[0m
[0;32m----> 1[0m [38;5;28;01mfrom[39;00m [38;5;21;01m.[39;00m[38;5;21;01mcarrega_dataset[39;00m [38;5;28;01mimport[39;00m [38;5;241m*[39m

File [0;32m~/work/Seminario_Nao_Parametrica/Seminario_Nao_Parametrica/src/utils/carrega_dataset.py:1[0m, in [0;36m<module>[0;34m[0m
[0;32m----> 1[0m [38;5;28;01mimport[39;00m [38;5;21;01mpandas[39;00m [38;5;28;01mas[39;00m [38;5;21;01mpd[39;00m
[1;32m      3[0m [38;5;66;03m#https://www.kaggle.com/datasets/mdmahmudulhasansuzan/students-adaptability-level-in-online-education[39;00m
[1;32m      4[0m CAMINHO_CSV [38;5;241m=[39m [38;5;124m'[39m[38;5;124m./datasets/students_adaptability_level_online_education.csv[39m[38;5;124m'[39m

[0;31mModuleNotFoundError[0m: No module named 'pandas'
ModuleNotFoundError: No module named 'pandas'

